
/*
===== MADE BY HAXMAN2'S .SCHEMATIC TO JAVA CONVERTING TOOLv0.2 ====
There is a tutorial on the forum thread on how to use this tool.
NOTE: The Block limit is 19,500 at the moment, meaning if your file is bigger then 20,000 lines, it MIGHT crash...
*/
package com.superhemi.PirateCraft.gen;
import java.util.Random;

import net.minecraft.world.World;
import net.minecraft.world.biome.BiomeGenBase;
import net.minecraft.world.gen.feature.WorldGenerator;
public class ShipWorldGenerator extends WorldGenerator
{
    public ShipWorldGenerator()
    {
    }
    public boolean generate(World world, Random rand, int i, int j, int k)
    {
    	BiomeGenBase b = world.getBiomeGenForCoords(i, k);
        if(b.biomeName.equals("Ocean")) {
                // Then we have ocean!
        }
int bID = 2;  /*2 is the block id for grass, so the structure going to spawn on grass*/
        if(world.getBlockId(i, j, k) != bID || world.getBlockId(i, j + 1, k) != 0 || world.getBlockId(i + 7, j, k) != bID || world.getBlockId(i + 7, j, k + 7) != bID || world.getBlockId(i, j, k + 7) != bID || world.getBlockId(i + 7, j + 1, k) != 0 || world.getBlockId(i + 7, j + 1, k + 7) != 0 || world.getBlockId(i, j + 1, k + 7) != 0)
        {
            return false;
        }
            world.setBlock(i + 3, j + 0, k + 20, 53);
            world.setBlock(i + 3, j + 0, k + 19, 53);
            world.setBlock(i + 3, j + 0, k + 18, 53);
            world.setBlock(i + 3, j + 0, k + 17, 53);
            world.setBlock(i + 3, j + 0, k + 16, 53);
            world.setBlock(i + 3, j + 0, k + 15, 53);
            world.setBlock(i + 3, j + 0, k + 14, 53);
            world.setBlock(i + 3, j + 0, k + 13, 53);
            world.setBlock(i + 3, j + 0, k + 12, 53);
            world.setBlock(i + 3, j + 0, k + 11, 53);
            world.setBlock(i + 3, j + 0, k + 10, 53);
            world.setBlock(i + 3, j + 0, k + 9, 53);
            world.setBlock(i + 4, j + 0, k + 21, 53);
            world.setBlock(i + 4, j + 0, k + 20, 5);
            world.setBlock(i + 4, j + 0, k + 19, 5);
            world.setBlock(i + 4, j + 0, k + 18, 5);
            world.setBlock(i + 4, j + 0, k + 17, 5);
            world.setBlock(i + 4, j + 0, k + 16, 5);
            world.setBlock(i + 4, j + 0, k + 15, 5);
            world.setBlock(i + 4, j + 0, k + 14, 5);
            world.setBlock(i + 4, j + 0, k + 13, 5);
            world.setBlock(i + 4, j + 0, k + 12, 5);
            world.setBlock(i + 4, j + 0, k + 11, 5);
            world.setBlock(i + 4, j + 0, k + 10, 5);
            world.setBlock(i + 4, j + 0, k + 9, 5);
            world.setBlock(i + 4, j + 0, k + 8, 53);
            world.setBlock(i + 4, j + 0, k + 7, 53);
            world.setBlock(i + 5, j + 0, k + 21, 53);
            world.setBlock(i + 5, j + 0, k + 20, 5);
            world.setBlock(i + 5, j + 0, k + 19, 5);
            world.setBlock(i + 5, j + 0, k + 18, 5);
            world.setBlock(i + 5, j + 0, k + 17, 5);
            world.setBlock(i + 5, j + 0, k + 16, 5);
            world.setBlock(i + 5, j + 0, k + 15, 5);
            world.setBlock(i + 5, j + 0, k + 14, 5);
            world.setBlock(i + 5, j + 0, k + 13, 5);
            world.setBlock(i + 5, j + 0, k + 12, 5);
            world.setBlock(i + 5, j + 0, k + 11, 5);
            world.setBlock(i + 5, j + 0, k + 10, 5);
            world.setBlock(i + 5, j + 0, k + 9, 5);
            world.setBlock(i + 5, j + 0, k + 8, 5);
            world.setBlock(i + 5, j + 0, k + 7, 5);
            world.setBlock(i + 5, j + 0, k + 6, 53);
            world.setBlock(i + 6, j + 0, k + 21, 53);
            world.setBlock(i + 6, j + 0, k + 20, 5);
            world.setBlock(i + 6, j + 0, k + 19, 5);
            world.setBlock(i + 6, j + 0, k + 18, 5);
            world.setBlock(i + 6, j + 0, k + 17, 5);
            world.setBlock(i + 6, j + 0, k + 16, 5);
            world.setBlock(i + 6, j + 0, k + 15, 5);
            world.setBlock(i + 6, j + 0, k + 14, 5);
            world.setBlock(i + 6, j + 0, k + 13, 5);
            world.setBlock(i + 6, j + 0, k + 12, 5);
            world.setBlock(i + 6, j + 0, k + 11, 5);
            world.setBlock(i + 6, j + 0, k + 10, 5);
            world.setBlock(i + 6, j + 0, k + 9, 5);
            world.setBlock(i + 6, j + 0, k + 8, 5);
            world.setBlock(i + 6, j + 0, k + 7, 5);
            world.setBlock(i + 6, j + 0, k + 6, 53);
            world.setBlock(i + 7, j + 0, k + 21, 53);
            world.setBlock(i + 7, j + 0, k + 20, 5);
            world.setBlock(i + 7, j + 0, k + 19, 5);
            world.setBlock(i + 7, j + 0, k + 18, 5);
            world.setBlock(i + 7, j + 0, k + 17, 5);
            world.setBlock(i + 7, j + 0, k + 16, 5);
            world.setBlock(i + 7, j + 0, k + 15, 5);
            world.setBlock(i + 7, j + 0, k + 14, 5);
            world.setBlock(i + 7, j + 0, k + 13, 5);
            world.setBlock(i + 7, j + 0, k + 12, 5);
            world.setBlock(i + 7, j + 0, k + 11, 5);
            world.setBlock(i + 7, j + 0, k + 10, 5);
            world.setBlock(i + 7, j + 0, k + 9, 5);
            world.setBlock(i + 7, j + 0, k + 8, 53);
            world.setBlock(i + 7, j + 0, k + 7, 53);
            world.setBlock(i + 8, j + 0, k + 20, 53);
            world.setBlock(i + 8, j + 0, k + 19, 53);
            world.setBlock(i + 8, j + 0, k + 18, 53);
            world.setBlock(i + 8, j + 0, k + 17, 53);
            world.setBlock(i + 8, j + 0, k + 16, 53);
            world.setBlock(i + 8, j + 0, k + 15, 53);
            world.setBlock(i + 8, j + 0, k + 14, 53);
            world.setBlock(i + 8, j + 0, k + 13, 53);
            world.setBlock(i + 8, j + 0, k + 12, 53);
            world.setBlock(i + 8, j + 0, k + 11, 53);
            world.setBlock(i + 8, j + 0, k + 10, 53);
            world.setBlock(i + 8, j + 0, k + 9, 53);
            world.setBlock(i + 2, j + 1, k + 20, 53);
            world.setBlock(i + 2, j + 1, k + 19, 53);
            world.setBlock(i + 2, j + 1, k + 18, 53);
            world.setBlock(i + 2, j + 1, k + 17, 53);
            world.setBlock(i + 2, j + 1, k + 16, 53);
            world.setBlock(i + 2, j + 1, k + 15, 53);
            world.setBlock(i + 2, j + 1, k + 14, 53);
            world.setBlock(i + 2, j + 1, k + 13, 53);
            world.setBlock(i + 2, j + 1, k + 12, 53);
            world.setBlock(i + 2, j + 1, k + 11, 53);
            world.setBlock(i + 2, j + 1, k + 10, 53);
            world.setBlock(i + 2, j + 1, k + 9, 53);
            world.setBlock(i + 3, j + 1, k + 21, 53);
            world.setBlock(i + 3, j + 1, k + 20, 5);
            world.setBlock(i + 3, j + 1, k + 19, 5);
            world.setBlock(i + 3, j + 1, k + 18, 5);
            world.setBlock(i + 3, j + 1, k + 17, 5);
            world.setBlock(i + 3, j + 1, k + 16, 5);
            world.setBlock(i + 3, j + 1, k + 15, 5);
            world.setBlock(i + 3, j + 1, k + 14, 5);
            world.setBlock(i + 3, j + 1, k + 13, 5);
            world.setBlock(i + 3, j + 1, k + 12, 5);
            world.setBlock(i + 3, j + 1, k + 11, 5);
            world.setBlock(i + 3, j + 1, k + 10, 5);
            world.setBlock(i + 3, j + 1, k + 9, 5);
            world.setBlock(i + 3, j + 1, k + 8, 53);
            world.setBlock(i + 3, j + 1, k + 7, 53);
            world.setBlock(i + 4, j + 1, k + 22, 53);
            world.setBlock(i + 4, j + 1, k + 21, 5);
            world.setBlock(i + 4, j + 1, k + 8, 5);
            world.setBlock(i + 4, j + 1, k + 7, 5);
            world.setBlock(i + 4, j + 1, k + 6, 53);
            world.setBlock(i + 4, j + 1, k + 5, 53);
            world.setBlock(i + 5, j + 1, k + 22, 53);
            world.setBlock(i + 5, j + 1, k + 21, 5);
            world.setBlock(i + 5, j + 1, k + 6, 5);
            world.setBlock(i + 5, j + 1, k + 5, 5);
            world.setBlock(i + 5, j + 1, k + 4, 53);
            world.setBlock(i + 6, j + 1, k + 22, 53);
            world.setBlock(i + 6, j + 1, k + 21, 5);
            world.setBlock(i + 6, j + 1, k + 6, 5);
            world.setBlock(i + 6, j + 1, k + 5, 5);
            world.setBlock(i + 6, j + 1, k + 4, 53);
            world.setBlock(i + 7, j + 1, k + 22, 53);
            world.setBlock(i + 7, j + 1, k + 21, 5);
            world.setBlock(i + 7, j + 1, k + 8, 5);
            world.setBlock(i + 7, j + 1, k + 7, 5);
            world.setBlock(i + 7, j + 1, k + 6, 53);
            world.setBlock(i + 7, j + 1, k + 5, 53);
            world.setBlock(i + 8, j + 1, k + 21, 53);
            world.setBlock(i + 8, j + 1, k + 20, 5);
            world.setBlock(i + 8, j + 1, k + 19, 5);
            world.setBlock(i + 8, j + 1, k + 18, 5);
            world.setBlock(i + 8, j + 1, k + 17, 5);
            world.setBlock(i + 8, j + 1, k + 16, 5);
            world.setBlock(i + 8, j + 1, k + 15, 5);
            world.setBlock(i + 8, j + 1, k + 14, 5);
            world.setBlock(i + 8, j + 1, k + 13, 5);
            world.setBlock(i + 8, j + 1, k + 12, 5);
            world.setBlock(i + 8, j + 1, k + 11, 5);
            world.setBlock(i + 8, j + 1, k + 10, 5);
            world.setBlock(i + 8, j + 1, k + 9, 5);
            world.setBlock(i + 8, j + 1, k + 8, 53);
            world.setBlock(i + 8, j + 1, k + 7, 53);
            world.setBlock(i + 9, j + 1, k + 20, 53);
            world.setBlock(i + 9, j + 1, k + 19, 53);
            world.setBlock(i + 9, j + 1, k + 18, 53);
            world.setBlock(i + 9, j + 1, k + 17, 53);
            world.setBlock(i + 9, j + 1, k + 16, 53);
            world.setBlock(i + 9, j + 1, k + 15, 53);
            world.setBlock(i + 9, j + 1, k + 14, 53);
            world.setBlock(i + 9, j + 1, k + 13, 53);
            world.setBlock(i + 9, j + 1, k + 12, 53);
            world.setBlock(i + 9, j + 1, k + 11, 53);
            world.setBlock(i + 9, j + 1, k + 10, 53);
            world.setBlock(i + 9, j + 1, k + 9, 53);
            world.setBlock(i + 1, j + 2, k + 20, 53);
            world.setBlock(i + 1, j + 2, k + 19, 53);
            world.setBlock(i + 1, j + 2, k + 18, 53);
            world.setBlock(i + 1, j + 2, k + 17, 53);
            world.setBlock(i + 1, j + 2, k + 16, 53);
            world.setBlock(i + 1, j + 2, k + 15, 53);
            world.setBlock(i + 1, j + 2, k + 14, 53);
            world.setBlock(i + 1, j + 2, k + 13, 53);
            world.setBlock(i + 1, j + 2, k + 12, 53);
            world.setBlock(i + 1, j + 2, k + 11, 53);
            world.setBlock(i + 1, j + 2, k + 10, 53);
            world.setBlock(i + 1, j + 2, k + 9, 53);
            world.setBlock(i + 2, j + 2, k + 21, 53);
            world.setBlock(i + 2, j + 2, k + 20, 5);
            world.setBlock(i + 2, j + 2, k + 19, 5);
            world.setBlock(i + 2, j + 2, k + 18, 5);
            world.setBlock(i + 2, j + 2, k + 17, 5);
            world.setBlock(i + 2, j + 2, k + 16, 5);
            world.setBlock(i + 2, j + 2, k + 15, 5);
            world.setBlock(i + 2, j + 2, k + 14, 5);
            world.setBlock(i + 2, j + 2, k + 13, 5);
            world.setBlock(i + 2, j + 2, k + 12, 5);
            world.setBlock(i + 2, j + 2, k + 11, 5);
            world.setBlock(i + 2, j + 2, k + 10, 5);
            world.setBlock(i + 2, j + 2, k + 9, 5);
            world.setBlock(i + 2, j + 2, k + 8, 53);
            world.setBlock(i + 2, j + 2, k + 7, 53);
            world.setBlock(i + 3, j + 2, k + 22, 53);
            world.setBlock(i + 3, j + 2, k + 21, 5);
            world.setBlock(i + 3, j + 2, k + 8, 5);
            world.setBlock(i + 3, j + 2, k + 7, 5);
            world.setBlock(i + 3, j + 2, k + 6, 53);
            world.setBlock(i + 3, j + 2, k + 5, 53);
            world.setBlock(i + 4, j + 2, k + 23, 53);
            world.setBlock(i + 4, j + 2, k + 22, 5);
            world.setBlock(i + 4, j + 2, k + 6, 5);
            world.setBlock(i + 4, j + 2, k + 5, 5);
            world.setBlock(i + 4, j + 2, k + 4, 53);
            world.setBlock(i + 5, j + 2, k + 23, 53);
            world.setBlock(i + 5, j + 2, k + 22, 5);
            world.setBlock(i + 5, j + 2, k + 16, 5);
            world.setBlock(i + 5, j + 2, k + 15, 65);
            world.setBlock(i + 5, j + 2, k + 14, 65);
            world.setBlock(i + 5, j + 2, k + 13, 5);
            world.setBlock(i + 5, j + 2, k + 4, 5);
            world.setBlock(i + 5, j + 2, k + 3, 53);
            world.setBlock(i + 6, j + 2, k + 23, 53);
            world.setBlock(i + 6, j + 2, k + 22, 5);
            world.setBlock(i + 6, j + 2, k + 16, 5);
            world.setBlock(i + 6, j + 2, k + 15, 65);
            world.setBlock(i + 6, j + 2, k + 14, 65);
            world.setBlock(i + 6, j + 2, k + 13, 5);
            world.setBlock(i + 6, j + 2, k + 4, 5);
            world.setBlock(i + 6, j + 2, k + 3, 53);
            world.setBlock(i + 7, j + 2, k + 23, 53);
            world.setBlock(i + 7, j + 2, k + 22, 5);
            world.setBlock(i + 7, j + 2, k + 6, 5);
            world.setBlock(i + 7, j + 2, k + 5, 5);
            world.setBlock(i + 7, j + 2, k + 4, 53);
            world.setBlock(i + 8, j + 2, k + 22, 53);
            world.setBlock(i + 8, j + 2, k + 21, 5);
            world.setBlock(i + 8, j + 2, k + 8, 5);
            world.setBlock(i + 8, j + 2, k + 7, 5);
            world.setBlock(i + 8, j + 2, k + 6, 53);
            world.setBlock(i + 8, j + 2, k + 5, 53);
            world.setBlock(i + 9, j + 2, k + 21, 53);
            world.setBlock(i + 9, j + 2, k + 20, 5);
            world.setBlock(i + 9, j + 2, k + 19, 5);
            world.setBlock(i + 9, j + 2, k + 18, 5);
            world.setBlock(i + 9, j + 2, k + 17, 5);
            world.setBlock(i + 9, j + 2, k + 16, 5);
            world.setBlock(i + 9, j + 2, k + 15, 5);
            world.setBlock(i + 9, j + 2, k + 14, 5);
            world.setBlock(i + 9, j + 2, k + 13, 5);
            world.setBlock(i + 9, j + 2, k + 12, 5);
            world.setBlock(i + 9, j + 2, k + 11, 5);
            world.setBlock(i + 9, j + 2, k + 10, 5);
            world.setBlock(i + 9, j + 2, k + 9, 5);
            world.setBlock(i + 9, j + 2, k + 8, 53);
            world.setBlock(i + 9, j + 2, k + 7, 53);
            world.setBlock(i + 10, j + 2, k + 20, 53);
            world.setBlock(i + 10, j + 2, k + 19, 53);
            world.setBlock(i + 10, j + 2, k + 18, 53);
            world.setBlock(i + 10, j + 2, k + 17, 53);
            world.setBlock(i + 10, j + 2, k + 16, 53);
            world.setBlock(i + 10, j + 2, k + 15, 53);
            world.setBlock(i + 10, j + 2, k + 14, 53);
            world.setBlock(i + 10, j + 2, k + 13, 53);
            world.setBlock(i + 10, j + 2, k + 12, 53);
            world.setBlock(i + 10, j + 2, k + 11, 53);
            world.setBlock(i + 10, j + 2, k + 10, 53);
            world.setBlock(i + 10, j + 2, k + 9, 53);
            world.setBlock(i + 0, j + 3, k + 18, 53);
            world.setBlock(i + 0, j + 3, k + 17, 53);
            world.setBlock(i + 0, j + 3, k + 16, 53);
            world.setBlock(i + 0, j + 3, k + 14, 53);
            world.setBlock(i + 0, j + 3, k + 12, 53);
            world.setBlock(i + 0, j + 3, k + 11, 53);
            world.setBlock(i + 0, j + 3, k + 10, 53);
            world.setBlock(i + 1, j + 3, k + 20, 5);
            world.setBlock(i + 1, j + 3, k + 19, 5);
            world.setBlock(i + 1, j + 3, k + 18, 5);
            world.setBlock(i + 1, j + 3, k + 17, 5);
            world.setBlock(i + 1, j + 3, k + 16, 5);
            world.setBlock(i + 1, j + 3, k + 15, 5);
            world.setBlock(i + 1, j + 3, k + 14, 5);
            world.setBlock(i + 1, j + 3, k + 13, 5);
            world.setBlock(i + 1, j + 3, k + 12, 5);
            world.setBlock(i + 1, j + 3, k + 11, 5);
            world.setBlock(i + 1, j + 3, k + 10, 5);
            world.setBlock(i + 1, j + 3, k + 9, 5);
            world.setBlock(i + 2, j + 3, k + 21, 5);
            world.setBlock(i + 2, j + 3, k + 17, 5);
            world.setBlock(i + 2, j + 3, k + 14, 5);
            world.setBlock(i + 2, j + 3, k + 11, 5);
            world.setBlock(i + 2, j + 3, k + 8, 5);
            world.setBlock(i + 2, j + 3, k + 7, 5);
            world.setBlock(i + 3, j + 3, k + 22, 5);
            world.setBlock(i + 3, j + 3, k + 6, 5);
            world.setBlock(i + 3, j + 3, k + 5, 5);
            world.setBlock(i + 4, j + 3, k + 23, 5);
            world.setBlock(i + 4, j + 3, k + 4, 5);
            world.setBlock(i + 5, j + 3, k + 23, 5);
            world.setBlock(i + 5, j + 3, k + 16, 5);
            world.setBlock(i + 5, j + 3, k + 15, 65);
            world.setBlock(i + 5, j + 3, k + 14, 65);
            world.setBlock(i + 5, j + 3, k + 13, 5);
            world.setBlock(i + 5, j + 3, k + 3, 5);
            world.setBlock(i + 6, j + 3, k + 23, 5);
            world.setBlock(i + 6, j + 3, k + 16, 5);
            world.setBlock(i + 6, j + 3, k + 15, 65);
            world.setBlock(i + 6, j + 3, k + 14, 65);
            world.setBlock(i + 6, j + 3, k + 13, 5);
            world.setBlock(i + 6, j + 3, k + 3, 5);
            world.setBlock(i + 7, j + 3, k + 23, 5);
            world.setBlock(i + 7, j + 3, k + 4, 5);
            world.setBlock(i + 8, j + 3, k + 22, 5);
            world.setBlock(i + 8, j + 3, k + 6, 5);
            world.setBlock(i + 8, j + 3, k + 5, 5);
            world.setBlock(i + 9, j + 3, k + 21, 5);
            world.setBlock(i + 9, j + 3, k + 17, 5);
            world.setBlock(i + 9, j + 3, k + 14, 5);
            world.setBlock(i + 9, j + 3, k + 11, 5);
            world.setBlock(i + 9, j + 3, k + 8, 5);
            world.setBlock(i + 9, j + 3, k + 7, 5);
            world.setBlock(i + 10, j + 3, k + 20, 5);
            world.setBlock(i + 10, j + 3, k + 19, 5);
            world.setBlock(i + 10, j + 3, k + 18, 5);
            world.setBlock(i + 10, j + 3, k + 17, 5);
            world.setBlock(i + 10, j + 3, k + 16, 5);
            world.setBlock(i + 10, j + 3, k + 15, 5);
            world.setBlock(i + 10, j + 3, k + 14, 5);
            world.setBlock(i + 10, j + 3, k + 13, 5);
            world.setBlock(i + 10, j + 3, k + 12, 5);
            world.setBlock(i + 10, j + 3, k + 11, 5);
            world.setBlock(i + 10, j + 3, k + 10, 5);
            world.setBlock(i + 10, j + 3, k + 9, 5);
            world.setBlock(i + 11, j + 3, k + 18, 53);
            world.setBlock(i + 11, j + 3, k + 17, 53);
            world.setBlock(i + 11, j + 3, k + 16, 53);
            world.setBlock(i + 11, j + 3, k + 14, 53);
            world.setBlock(i + 11, j + 3, k + 12, 53);
            world.setBlock(i + 11, j + 3, k + 11, 53);
            world.setBlock(i + 11, j + 3, k + 10, 53);
            world.setBlock(i + 1, j + 4, k + 20, 5);
            world.setBlock(i + 1, j + 4, k + 19, 5);
            world.setBlock(i + 1, j + 4, k + 18, 5);
            world.setBlock(i + 1, j + 4, k + 16, 5);
            world.setBlock(i + 1, j + 4, k + 15, 5);
            world.setBlock(i + 1, j + 4, k + 13, 5);
            world.setBlock(i + 1, j + 4, k + 12, 5);
            world.setBlock(i + 1, j + 4, k + 10, 5);
            world.setBlock(i + 1, j + 4, k + 9, 5);
            world.setBlock(i + 2, j + 4, k + 21, 5);
            world.setBlock(i + 2, j + 4, k + 8, 5);
            world.setBlock(i + 2, j + 4, k + 7, 5);
            world.setBlock(i + 3, j + 4, k + 22, 5);
            world.setBlock(i + 3, j + 4, k + 6, 5);
            world.setBlock(i + 3, j + 4, k + 5, 5);
            world.setBlock(i + 4, j + 4, k + 23, 5);
            world.setBlock(i + 4, j + 4, k + 4, 5);
            world.setBlock(i + 5, j + 4, k + 23, 5);
            world.setBlock(i + 5, j + 4, k + 16, 5);
            world.setBlock(i + 5, j + 4, k + 15, 65);
            world.setBlock(i + 5, j + 4, k + 14, 65);
            world.setBlock(i + 5, j + 4, k + 13, 5);
            world.setBlock(i + 5, j + 4, k + 3, 5);
            world.setBlock(i + 5, j + 4, k + 2, 53);
            world.setBlock(i + 6, j + 4, k + 23, 5);
            world.setBlock(i + 6, j + 4, k + 16, 5);
            world.setBlock(i + 6, j + 4, k + 15, 65);
            world.setBlock(i + 6, j + 4, k + 14, 65);
            world.setBlock(i + 6, j + 4, k + 13, 5);
            world.setBlock(i + 6, j + 4, k + 3, 5);
            world.setBlock(i + 6, j + 4, k + 2, 53);
            world.setBlock(i + 7, j + 4, k + 23, 5);
            world.setBlock(i + 7, j + 4, k + 4, 5);
            world.setBlock(i + 8, j + 4, k + 22, 5);
            world.setBlock(i + 8, j + 4, k + 6, 5);
            world.setBlock(i + 8, j + 4, k + 5, 5);
            world.setBlock(i + 9, j + 4, k + 21, 5);
            world.setBlock(i + 9, j + 4, k + 8, 5);
            world.setBlock(i + 9, j + 4, k + 7, 5);
            world.setBlock(i + 10, j + 4, k + 20, 5);
            world.setBlock(i + 10, j + 4, k + 19, 5);
            world.setBlock(i + 10, j + 4, k + 18, 5);
            world.setBlock(i + 10, j + 4, k + 16, 5);
            world.setBlock(i + 10, j + 4, k + 15, 5);
            world.setBlock(i + 10, j + 4, k + 13, 5);
            world.setBlock(i + 10, j + 4, k + 12, 5);
            world.setBlock(i + 10, j + 4, k + 10, 5);
            world.setBlock(i + 10, j + 4, k + 9, 5);
            world.setBlock(i + 0, j + 5, k + 17, 53);
            world.setBlock(i + 0, j + 5, k + 14, 53);
            world.setBlock(i + 0, j + 5, k + 11, 53);
            world.setBlock(i + 1, j + 5, k + 20, 5);
            world.setBlock(i + 1, j + 5, k + 19, 5);
            world.setBlock(i + 1, j + 5, k + 18, 5);
            world.setBlock(i + 1, j + 5, k + 17, 5);
            world.setBlock(i + 1, j + 5, k + 16, 5);
            world.setBlock(i + 1, j + 5, k + 15, 5);
            world.setBlock(i + 1, j + 5, k + 14, 5);
            world.setBlock(i + 1, j + 5, k + 13, 5);
            world.setBlock(i + 1, j + 5, k + 12, 5);
            world.setBlock(i + 1, j + 5, k + 11, 5);
            world.setBlock(i + 1, j + 5, k + 10, 5);
            world.setBlock(i + 1, j + 5, k + 9, 5);
            world.setBlock(i + 2, j + 5, k + 21, 5);
            world.setBlock(i + 2, j + 5, k + 9, 5);
            world.setBlock(i + 2, j + 5, k + 8, 5);
            world.setBlock(i + 2, j + 5, k + 7, 5);
            world.setBlock(i + 3, j + 5, k + 22, 5);
            world.setBlock(i + 3, j + 5, k + 9, 5);
            world.setBlock(i + 3, j + 5, k + 8, 5);
            world.setBlock(i + 3, j + 5, k + 7, 5);
            world.setBlock(i + 3, j + 5, k + 6, 5);
            world.setBlock(i + 3, j + 5, k + 5, 5);
            world.setBlock(i + 4, j + 5, k + 23, 5);
            world.setBlock(i + 4, j + 5, k + 9, 5);
            world.setBlock(i + 4, j + 5, k + 8, 5);
            world.setBlock(i + 4, j + 5, k + 7, 5);
            world.setBlock(i + 4, j + 5, k + 6, 5);
            world.setBlock(i + 4, j + 5, k + 5, 5);
            world.setBlock(i + 4, j + 5, k + 4, 5);
            world.setBlock(i + 5, j + 5, k + 23, 5);
            world.setBlock(i + 5, j + 5, k + 16, 5);
            world.setBlock(i + 5, j + 5, k + 15, 65);
            world.setBlock(i + 5, j + 5, k + 14, 65);
            world.setBlock(i + 5, j + 5, k + 13, 5);
            world.setBlock(i + 5, j + 5, k + 9, 5);
            world.setBlock(i + 5, j + 5, k + 8, 5);
            world.setBlock(i + 5, j + 5, k + 7, 5);
            world.setBlock(i + 5, j + 5, k + 6, 5);
            world.setBlock(i + 5, j + 5, k + 5, 5);
            world.setBlock(i + 5, j + 5, k + 4, 5);
            world.setBlock(i + 5, j + 5, k + 3, 5);
            world.setBlock(i + 5, j + 5, k + 2, 5);
            world.setBlock(i + 6, j + 5, k + 23, 5);
            world.setBlock(i + 6, j + 5, k + 16, 5);
            world.setBlock(i + 6, j + 5, k + 15, 65);
            world.setBlock(i + 6, j + 5, k + 14, 65);
            world.setBlock(i + 6, j + 5, k + 13, 5);
            world.setBlock(i + 6, j + 5, k + 9, 5);
            world.setBlock(i + 6, j + 5, k + 8, 5);
            world.setBlock(i + 6, j + 5, k + 7, 5);
            world.setBlock(i + 6, j + 5, k + 6, 5);
            world.setBlock(i + 6, j + 5, k + 5, 5);
            world.setBlock(i + 6, j + 5, k + 4, 5);
            world.setBlock(i + 6, j + 5, k + 3, 5);
            world.setBlock(i + 6, j + 5, k + 2, 5);
            world.setBlock(i + 7, j + 5, k + 23, 5);
            world.setBlock(i + 7, j + 5, k + 9, 5);
            world.setBlock(i + 7, j + 5, k + 8, 5);
            world.setBlock(i + 7, j + 5, k + 7, 5);
            world.setBlock(i + 7, j + 5, k + 6, 5);
            world.setBlock(i + 7, j + 5, k + 5, 5);
            world.setBlock(i + 7, j + 5, k + 4, 5);
            world.setBlock(i + 8, j + 5, k + 22, 5);
            world.setBlock(i + 8, j + 5, k + 9, 5);
            world.setBlock(i + 8, j + 5, k + 8, 5);
            world.setBlock(i + 8, j + 5, k + 7, 5);
            world.setBlock(i + 8, j + 5, k + 6, 5);
            world.setBlock(i + 8, j + 5, k + 5, 5);
            world.setBlock(i + 9, j + 5, k + 21, 5);
            world.setBlock(i + 9, j + 5, k + 9, 5);
            world.setBlock(i + 9, j + 5, k + 8, 5);
            world.setBlock(i + 9, j + 5, k + 7, 5);
            world.setBlock(i + 10, j + 5, k + 20, 5);
            world.setBlock(i + 10, j + 5, k + 19, 5);
            world.setBlock(i + 10, j + 5, k + 18, 5);
            world.setBlock(i + 10, j + 5, k + 17, 5);
            world.setBlock(i + 10, j + 5, k + 16, 5);
            world.setBlock(i + 10, j + 5, k + 15, 5);
            world.setBlock(i + 10, j + 5, k + 14, 5);
            world.setBlock(i + 10, j + 5, k + 13, 5);
            world.setBlock(i + 10, j + 5, k + 12, 5);
            world.setBlock(i + 10, j + 5, k + 11, 5);
            world.setBlock(i + 10, j + 5, k + 10, 5);
            world.setBlock(i + 10, j + 5, k + 9, 5);
            world.setBlock(i + 11, j + 5, k + 17, 53);
            world.setBlock(i + 11, j + 5, k + 14, 53);
            world.setBlock(i + 11, j + 5, k + 11, 53);
            world.setBlock(i + 1, j + 6, k + 20, 5);
            world.setBlock(i + 1, j + 6, k + 19, 5);
            world.setBlock(i + 1, j + 6, k + 18, 5);
            world.setBlock(i + 1, j + 6, k + 17, 5);
            world.setBlock(i + 1, j + 6, k + 16, 5);
            world.setBlock(i + 1, j + 6, k + 15, 5);
            world.setBlock(i + 1, j + 6, k + 14, 5);
            world.setBlock(i + 1, j + 6, k + 13, 5);
            world.setBlock(i + 1, j + 6, k + 12, 5);
            world.setBlock(i + 1, j + 6, k + 11, 5);
            world.setBlock(i + 1, j + 6, k + 10, 5);
            world.setBlock(i + 1, j + 6, k + 9, 5);
            world.setBlock(i + 2, j + 6, k + 21, 5);
            world.setBlock(i + 2, j + 6, k + 20, 5);
            world.setBlock(i + 2, j + 6, k + 19, 5);
            world.setBlock(i + 2, j + 6, k + 18, 5);
            world.setBlock(i + 2, j + 6, k + 17, 5);
            world.setBlock(i + 2, j + 6, k + 16, 5);
            world.setBlock(i + 2, j + 6, k + 15, 5);
            world.setBlock(i + 2, j + 6, k + 14, 5);
            world.setBlock(i + 2, j + 6, k + 13, 5);
            world.setBlock(i + 2, j + 6, k + 12, 5);
            world.setBlock(i + 2, j + 6, k + 11, 5);
            world.setBlock(i + 2, j + 6, k + 10, 5);
            world.setBlock(i + 2, j + 6, k + 9, 5);
            world.setBlock(i + 2, j + 6, k + 8, 5);
            world.setBlock(i + 2, j + 6, k + 7, 5);
            world.setBlock(i + 3, j + 6, k + 22, 5);
            world.setBlock(i + 3, j + 6, k + 21, 5);
            world.setBlock(i + 3, j + 6, k + 20, 5);
            world.setBlock(i + 3, j + 6, k + 19, 5);
            world.setBlock(i + 3, j + 6, k + 18, 5);
            world.setBlock(i + 3, j + 6, k + 17, 5);
            world.setBlock(i + 3, j + 6, k + 16, 5);
            world.setBlock(i + 3, j + 6, k + 15, 5);
            world.setBlock(i + 3, j + 6, k + 14, 5);
            world.setBlock(i + 3, j + 6, k + 13, 5);
            world.setBlock(i + 3, j + 6, k + 12, 5);
            world.setBlock(i + 3, j + 6, k + 11, 5);
            world.setBlock(i + 3, j + 6, k + 10, 5);
            world.setBlock(i + 3, j + 6, k + 9, 5);
            world.setBlock(i + 3, j + 6, k + 8, 5);
            world.setBlock(i + 3, j + 6, k + 6, 5);
            world.setBlock(i + 3, j + 6, k + 5, 5);
            world.setBlock(i + 4, j + 6, k + 23, 5);
            world.setBlock(i + 4, j + 6, k + 22, 5);
            world.setBlock(i + 4, j + 6, k + 21, 5);
            world.setBlock(i + 4, j + 6, k + 20, 5);
            world.setBlock(i + 4, j + 6, k + 19, 5);
            world.setBlock(i + 4, j + 6, k + 18, 5);
            world.setBlock(i + 4, j + 6, k + 17, 5);
            world.setBlock(i + 4, j + 6, k + 16, 5);
            world.setBlock(i + 4, j + 6, k + 15, 5);
            world.setBlock(i + 4, j + 6, k + 14, 5);
            world.setBlock(i + 4, j + 6, k + 13, 5);
            world.setBlock(i + 4, j + 6, k + 12, 5);
            world.setBlock(i + 4, j + 6, k + 11, 5);
            world.setBlock(i + 4, j + 6, k + 10, 53);
            world.setBlock(i + 4, j + 6, k + 8, 64);
            world.setBlock(i + 4, j + 6, k + 4, 5);
            world.setBlock(i + 5, j + 6, k + 23, 5);
            world.setBlock(i + 5, j + 6, k + 22, 5);
            world.setBlock(i + 5, j + 6, k + 21, 5);
            world.setBlock(i + 5, j + 6, k + 20, 5);
            world.setBlock(i + 5, j + 6, k + 19, 5);
            world.setBlock(i + 5, j + 6, k + 18, 5);
            world.setBlock(i + 5, j + 6, k + 17, 5);
            world.setBlock(i + 5, j + 6, k + 16, 5);
            world.setBlock(i + 5, j + 6, k + 15, 96);
            world.setBlock(i + 5, j + 6, k + 14, 96);
            world.setBlock(i + 5, j + 6, k + 13, 5);
            world.setBlock(i + 5, j + 6, k + 12, 5);
            world.setBlock(i + 5, j + 6, k + 11, 5);
            world.setBlock(i + 5, j + 6, k + 10, 5);
            world.setBlock(i + 5, j + 6, k + 9, 17);
            world.setBlock(i + 5, j + 6, k + 8, 5);
            world.setBlock(i + 5, j + 6, k + 3, 5);
            world.setBlock(i + 5, j + 6, k + 2, 5);
            world.setBlock(i + 5, j + 6, k + 1, 53);
            world.setBlock(i + 6, j + 6, k + 23, 5);
            world.setBlock(i + 6, j + 6, k + 22, 5);
            world.setBlock(i + 6, j + 6, k + 21, 5);
            world.setBlock(i + 6, j + 6, k + 20, 5);
            world.setBlock(i + 6, j + 6, k + 19, 5);
            world.setBlock(i + 6, j + 6, k + 18, 5);
            world.setBlock(i + 6, j + 6, k + 17, 5);
            world.setBlock(i + 6, j + 6, k + 16, 5);
            world.setBlock(i + 6, j + 6, k + 15, 96);
            world.setBlock(i + 6, j + 6, k + 14, 96);
            world.setBlock(i + 6, j + 6, k + 13, 5);
            world.setBlock(i + 6, j + 6, k + 12, 5);
            world.setBlock(i + 6, j + 6, k + 11, 5);
            world.setBlock(i + 6, j + 6, k + 10, 5);
            world.setBlock(i + 6, j + 6, k + 9, 17);
            world.setBlock(i + 6, j + 6, k + 8, 5);
            world.setBlock(i + 6, j + 6, k + 3, 5);
            world.setBlock(i + 6, j + 6, k + 2, 5);
            world.setBlock(i + 6, j + 6, k + 1, 53);
            world.setBlock(i + 7, j + 6, k + 23, 5);
            world.setBlock(i + 7, j + 6, k + 22, 5);
            world.setBlock(i + 7, j + 6, k + 21, 5);
            world.setBlock(i + 7, j + 6, k + 20, 5);
            world.setBlock(i + 7, j + 6, k + 19, 5);
            world.setBlock(i + 7, j + 6, k + 18, 5);
            world.setBlock(i + 7, j + 6, k + 17, 5);
            world.setBlock(i + 7, j + 6, k + 16, 5);
            world.setBlock(i + 7, j + 6, k + 15, 5);
            world.setBlock(i + 7, j + 6, k + 14, 5);
            world.setBlock(i + 7, j + 6, k + 13, 5);
            world.setBlock(i + 7, j + 6, k + 12, 5);
            world.setBlock(i + 7, j + 6, k + 11, 5);
            world.setBlock(i + 7, j + 6, k + 10, 53);
            world.setBlock(i + 7, j + 6, k + 8, 64);
            world.setBlock(i + 7, j + 6, k + 4, 5);
            world.setBlock(i + 8, j + 6, k + 22, 5);
            world.setBlock(i + 8, j + 6, k + 21, 5);
            world.setBlock(i + 8, j + 6, k + 20, 5);
            world.setBlock(i + 8, j + 6, k + 19, 5);
            world.setBlock(i + 8, j + 6, k + 18, 5);
            world.setBlock(i + 8, j + 6, k + 17, 5);
            world.setBlock(i + 8, j + 6, k + 16, 5);
            world.setBlock(i + 8, j + 6, k + 15, 5);
            world.setBlock(i + 8, j + 6, k + 14, 5);
            world.setBlock(i + 8, j + 6, k + 13, 5);
            world.setBlock(i + 8, j + 6, k + 12, 5);
            world.setBlock(i + 8, j + 6, k + 11, 5);
            world.setBlock(i + 8, j + 6, k + 10, 5);
            world.setBlock(i + 8, j + 6, k + 9, 5);
            world.setBlock(i + 8, j + 6, k + 8, 5);
            world.setBlock(i + 8, j + 6, k + 6, 5);
            world.setBlock(i + 8, j + 6, k + 5, 5);
            world.setBlock(i + 9, j + 6, k + 21, 5);
            world.setBlock(i + 9, j + 6, k + 20, 5);
            world.setBlock(i + 9, j + 6, k + 19, 5);
            world.setBlock(i + 9, j + 6, k + 18, 5);
            world.setBlock(i + 9, j + 6, k + 17, 5);
            world.setBlock(i + 9, j + 6, k + 16, 5);
            world.setBlock(i + 9, j + 6, k + 15, 5);
            world.setBlock(i + 9, j + 6, k + 14, 5);
            world.setBlock(i + 9, j + 6, k + 13, 5);
            world.setBlock(i + 9, j + 6, k + 12, 5);
            world.setBlock(i + 9, j + 6, k + 11, 5);
            world.setBlock(i + 9, j + 6, k + 10, 5);
            world.setBlock(i + 9, j + 6, k + 9, 5);
            world.setBlock(i + 9, j + 6, k + 8, 5);
            world.setBlock(i + 9, j + 6, k + 7, 5);
            world.setBlock(i + 10, j + 6, k + 20, 5);
            world.setBlock(i + 10, j + 6, k + 19, 5);
            world.setBlock(i + 10, j + 6, k + 18, 5);
            world.setBlock(i + 10, j + 6, k + 17, 5);
            world.setBlock(i + 10, j + 6, k + 16, 5);
            world.setBlock(i + 10, j + 6, k + 15, 5);
            world.setBlock(i + 10, j + 6, k + 14, 5);
            world.setBlock(i + 10, j + 6, k + 13, 5);
            world.setBlock(i + 10, j + 6, k + 12, 5);
            world.setBlock(i + 10, j + 6, k + 11, 5);
            world.setBlock(i + 10, j + 6, k + 10, 5);
            world.setBlock(i + 10, j + 6, k + 9, 5);
            world.setBlock(i + 1, j + 7, k + 21, 53);
            world.setBlock(i + 1, j + 7, k + 20, 5);
            world.setBlock(i + 1, j + 7, k + 19, 5);
            world.setBlock(i + 1, j + 7, k + 18, 5);
            world.setBlock(i + 1, j + 7, k + 17, 5);
            world.setBlock(i + 1, j + 7, k + 16, 5);
            world.setBlock(i + 1, j + 7, k + 15, 5);
            world.setBlock(i + 1, j + 7, k + 14, 5);
            world.setBlock(i + 1, j + 7, k + 13, 5);
            world.setBlock(i + 1, j + 7, k + 12, 5);
            world.setBlock(i + 1, j + 7, k + 11, 5);
            world.setBlock(i + 1, j + 7, k + 10, 5);
            world.setBlock(i + 1, j + 7, k + 9, 5);
            world.setBlock(i + 1, j + 7, k + 8, 53);
            world.setBlock(i + 2, j + 7, k + 22, 53);
            world.setBlock(i + 2, j + 7, k + 21, 5);
            world.setBlock(i + 2, j + 7, k + 19, 5);
            world.setBlock(i + 2, j + 7, k + 18, 53);
            world.setBlock(i + 2, j + 7, k + 17, 53);
            world.setBlock(i + 2, j + 7, k + 10, 53);
            world.setBlock(i + 2, j + 7, k + 9, 5);
            world.setBlock(i + 2, j + 7, k + 8, 5);
            world.setBlock(i + 2, j + 7, k + 7, 5);
            world.setBlock(i + 2, j + 7, k + 6, 53);
            world.setBlock(i + 3, j + 7, k + 23, 53);
            world.setBlock(i + 3, j + 7, k + 22, 5);
            world.setBlock(i + 3, j + 7, k + 19, 5);
            world.setBlock(i + 3, j + 7, k + 18, 5);
            world.setBlock(i + 3, j + 7, k + 17, 53);
            world.setBlock(i + 3, j + 7, k + 10, 53);
            world.setBlock(i + 3, j + 7, k + 9, 5);
            world.setBlock(i + 3, j + 7, k + 8, 5);
            world.setBlock(i + 3, j + 7, k + 6, 5);
            world.setBlock(i + 3, j + 7, k + 5, 5);
            world.setBlock(i + 3, j + 7, k + 4, 53);
            world.setBlock(i + 4, j + 7, k + 23, 5);
            world.setBlock(i + 4, j + 7, k + 19, 64);
            world.setBlock(i + 4, j + 7, k + 8, 64);
            world.setBlock(i + 4, j + 7, k + 4, 5);
            world.setBlock(i + 4, j + 7, k + 3, 53);
            world.setBlock(i + 5, j + 7, k + 23, 5);
            world.setBlock(i + 5, j + 7, k + 19, 5);
            world.setBlock(i + 5, j + 7, k + 18, 17);
            world.setBlock(i + 5, j + 7, k + 17, 17);
            world.setBlock(i + 5, j + 7, k + 9, 17);
            world.setBlock(i + 5, j + 7, k + 8, 5);
            world.setBlock(i + 5, j + 7, k + 3, 5);
            world.setBlock(i + 5, j + 7, k + 2, 5);
            world.setBlock(i + 5, j + 7, k + 1, 5);
            world.setBlock(i + 6, j + 7, k + 23, 5);
            world.setBlock(i + 6, j + 7, k + 19, 5);
            world.setBlock(i + 6, j + 7, k + 18, 17);
            world.setBlock(i + 6, j + 7, k + 17, 17);
            world.setBlock(i + 6, j + 7, k + 9, 17);
            world.setBlock(i + 6, j + 7, k + 8, 5);
            world.setBlock(i + 6, j + 7, k + 3, 5);
            world.setBlock(i + 6, j + 7, k + 2, 5);
            world.setBlock(i + 6, j + 7, k + 1, 5);
            world.setBlock(i + 7, j + 7, k + 23, 5);
            world.setBlock(i + 7, j + 7, k + 19, 64);
            world.setBlock(i + 7, j + 7, k + 8, 64);
            world.setBlock(i + 7, j + 7, k + 4, 5);
            world.setBlock(i + 7, j + 7, k + 3, 53);
            world.setBlock(i + 8, j + 7, k + 23, 53);
            world.setBlock(i + 8, j + 7, k + 22, 5);
            world.setBlock(i + 8, j + 7, k + 19, 5);
            world.setBlock(i + 8, j + 7, k + 18, 5);
            world.setBlock(i + 8, j + 7, k + 17, 53);
            world.setBlock(i + 8, j + 7, k + 10, 53);
            world.setBlock(i + 8, j + 7, k + 9, 5);
            world.setBlock(i + 8, j + 7, k + 8, 5);
            world.setBlock(i + 8, j + 7, k + 6, 5);
            world.setBlock(i + 8, j + 7, k + 5, 5);
            world.setBlock(i + 8, j + 7, k + 4, 53);
            world.setBlock(i + 9, j + 7, k + 22, 53);
            world.setBlock(i + 9, j + 7, k + 21, 5);
            world.setBlock(i + 9, j + 7, k + 19, 5);
            world.setBlock(i + 9, j + 7, k + 18, 5);
            world.setBlock(i + 9, j + 7, k + 17, 53);
            world.setBlock(i + 9, j + 7, k + 10, 53);
            world.setBlock(i + 9, j + 7, k + 9, 5);
            world.setBlock(i + 9, j + 7, k + 8, 5);
            world.setBlock(i + 9, j + 7, k + 7, 5);
            world.setBlock(i + 9, j + 7, k + 6, 53);
            world.setBlock(i + 10, j + 7, k + 21, 53);
            world.setBlock(i + 10, j + 7, k + 20, 5);
            world.setBlock(i + 10, j + 7, k + 19, 5);
            world.setBlock(i + 10, j + 7, k + 18, 5);
            world.setBlock(i + 10, j + 7, k + 17, 5);
            world.setBlock(i + 10, j + 7, k + 16, 5);
            world.setBlock(i + 10, j + 7, k + 15, 5);
            world.setBlock(i + 10, j + 7, k + 14, 5);
            world.setBlock(i + 10, j + 7, k + 13, 5);
            world.setBlock(i + 10, j + 7, k + 12, 5);
            world.setBlock(i + 10, j + 7, k + 11, 5);
            world.setBlock(i + 10, j + 7, k + 10, 5);
            world.setBlock(i + 10, j + 7, k + 9, 5);
            world.setBlock(i + 10, j + 7, k + 8, 53);
            world.setBlock(i + 1, j + 8, k + 21, 5);
            world.setBlock(i + 1, j + 8, k + 20, 5);
            world.setBlock(i + 1, j + 8, k + 19, 5);
            world.setBlock(i + 1, j + 8, k + 18, 5);
            world.setBlock(i + 1, j + 8, k + 17, 85);
            world.setBlock(i + 1, j + 8, k + 16, 85);
            world.setBlock(i + 1, j + 8, k + 15, 85);
            world.setBlock(i + 1, j + 8, k + 14, 85);
            world.setBlock(i + 1, j + 8, k + 13, 85);
            world.setBlock(i + 1, j + 8, k + 12, 85);
            world.setBlock(i + 1, j + 8, k + 11, 85);
            world.setBlock(i + 1, j + 8, k + 10, 5);
            world.setBlock(i + 1, j + 8, k + 9, 5);
            world.setBlock(i + 1, j + 8, k + 8, 5);
            world.setBlock(i + 2, j + 8, k + 22, 5);
            world.setBlock(i + 2, j + 8, k + 21, 5);
            world.setBlock(i + 2, j + 8, k + 19, 5);
            world.setBlock(i + 2, j + 8, k + 18, 53);
            world.setBlock(i + 2, j + 8, k + 9, 53);
            world.setBlock(i + 2, j + 8, k + 8, 5);
            world.setBlock(i + 2, j + 8, k + 7, 5);
            world.setBlock(i + 2, j + 8, k + 6, 5);
            world.setBlock(i + 3, j + 8, k + 23, 5);
            world.setBlock(i + 3, j + 8, k + 22, 5);
            world.setBlock(i + 3, j + 8, k + 19, 5);
            world.setBlock(i + 3, j + 8, k + 18, 53);
            world.setBlock(i + 3, j + 8, k + 9, 53);
            world.setBlock(i + 3, j + 8, k + 8, 5);
            world.setBlock(i + 3, j + 8, k + 7, 5);
            world.setBlock(i + 3, j + 8, k + 6, 5);
            world.setBlock(i + 3, j + 8, k + 5, 5);
            world.setBlock(i + 3, j + 8, k + 4, 5);
            world.setBlock(i + 4, j + 8, k + 23, 5);
            world.setBlock(i + 4, j + 8, k + 19, 64);
            world.setBlock(i + 4, j + 8, k + 8, 5);
            world.setBlock(i + 4, j + 8, k + 7, 5);
            world.setBlock(i + 4, j + 8, k + 6, 5);
            world.setBlock(i + 4, j + 8, k + 5, 5);
            world.setBlock(i + 4, j + 8, k + 4, 5);
            world.setBlock(i + 4, j + 8, k + 3, 5);
            world.setBlock(i + 4, j + 8, k + 2, 53);
            world.setBlock(i + 4, j + 8, k + 1, 53);
            world.setBlock(i + 4, j + 8, k + 0, 53);
            world.setBlock(i + 5, j + 8, k + 23, 85);
            world.setBlock(i + 5, j + 8, k + 19, 5);
            world.setBlock(i + 5, j + 8, k + 18, 17);
            world.setBlock(i + 5, j + 8, k + 17, 17);
            world.setBlock(i + 5, j + 8, k + 9, 17);
            world.setBlock(i + 5, j + 8, k + 8, 5);
            world.setBlock(i + 5, j + 8, k + 7, 5);
            world.setBlock(i + 5, j + 8, k + 6, 5);
            world.setBlock(i + 5, j + 8, k + 5, 5);
            world.setBlock(i + 5, j + 8, k + 4, 5);
            world.setBlock(i + 5, j + 8, k + 3, 5);
            world.setBlock(i + 5, j + 8, k + 2, 5);
            world.setBlock(i + 5, j + 8, k + 1, 5);
            world.setBlock(i + 5, j + 8, k + 0, 53);
            world.setBlock(i + 6, j + 8, k + 23, 85);
            world.setBlock(i + 6, j + 8, k + 19, 5);
            world.setBlock(i + 6, j + 8, k + 18, 17);
            world.setBlock(i + 6, j + 8, k + 17, 17);
            world.setBlock(i + 6, j + 8, k + 9, 17);
            world.setBlock(i + 6, j + 8, k + 8, 5);
            world.setBlock(i + 6, j + 8, k + 7, 5);
            world.setBlock(i + 6, j + 8, k + 6, 5);
            world.setBlock(i + 6, j + 8, k + 5, 5);
            world.setBlock(i + 6, j + 8, k + 4, 5);
            world.setBlock(i + 6, j + 8, k + 3, 5);
            world.setBlock(i + 6, j + 8, k + 2, 5);
            world.setBlock(i + 6, j + 8, k + 1, 5);
            world.setBlock(i + 6, j + 8, k + 0, 53);
            world.setBlock(i + 7, j + 8, k + 23, 5);
            world.setBlock(i + 7, j + 8, k + 19, 64);
            world.setBlock(i + 7, j + 8, k + 8, 5);
            world.setBlock(i + 7, j + 8, k + 7, 5);
            world.setBlock(i + 7, j + 8, k + 6, 5);
            world.setBlock(i + 7, j + 8, k + 5, 5);
            world.setBlock(i + 7, j + 8, k + 4, 5);
            world.setBlock(i + 7, j + 8, k + 3, 5);
            world.setBlock(i + 7, j + 8, k + 2, 53);
            world.setBlock(i + 7, j + 8, k + 1, 53);
            world.setBlock(i + 7, j + 8, k + 0, 53);
            world.setBlock(i + 8, j + 8, k + 23, 5);
            world.setBlock(i + 8, j + 8, k + 22, 5);
            world.setBlock(i + 8, j + 8, k + 19, 5);
            world.setBlock(i + 8, j + 8, k + 18, 53);
            world.setBlock(i + 8, j + 8, k + 9, 53);
            world.setBlock(i + 8, j + 8, k + 8, 5);
            world.setBlock(i + 8, j + 8, k + 7, 5);
            world.setBlock(i + 8, j + 8, k + 6, 5);
            world.setBlock(i + 8, j + 8, k + 5, 5);
            world.setBlock(i + 8, j + 8, k + 4, 5);
            world.setBlock(i + 9, j + 8, k + 22, 5);
            world.setBlock(i + 9, j + 8, k + 21, 5);
            world.setBlock(i + 9, j + 8, k + 19, 5);
            world.setBlock(i + 9, j + 8, k + 18, 53);
            world.setBlock(i + 9, j + 8, k + 9, 53);
            world.setBlock(i + 9, j + 8, k + 8, 5);
            world.setBlock(i + 9, j + 8, k + 7, 5);
            world.setBlock(i + 9, j + 8, k + 6, 5);
            world.setBlock(i + 10, j + 8, k + 21, 5);
            world.setBlock(i + 10, j + 8, k + 20, 5);
            world.setBlock(i + 10, j + 8, k + 19, 5);
            world.setBlock(i + 10, j + 8, k + 18, 5);
            world.setBlock(i + 10, j + 8, k + 17, 85);
            world.setBlock(i + 10, j + 8, k + 16, 85);
            world.setBlock(i + 10, j + 8, k + 15, 85);
            world.setBlock(i + 10, j + 8, k + 14, 85);
            world.setBlock(i + 10, j + 8, k + 13, 85);
            world.setBlock(i + 10, j + 8, k + 12, 85);
            world.setBlock(i + 10, j + 8, k + 11, 85);
            world.setBlock(i + 10, j + 8, k + 10, 5);
            world.setBlock(i + 10, j + 8, k + 9, 5);
            world.setBlock(i + 10, j + 8, k + 8, 5);
            world.setBlock(i + 1, j + 9, k + 21, 5);
            world.setBlock(i + 1, j + 9, k + 20, 5);
            world.setBlock(i + 1, j + 9, k + 19, 5);
            world.setBlock(i + 1, j + 9, k + 18, 85);
            world.setBlock(i + 1, j + 9, k + 10, 85);
            world.setBlock(i + 1, j + 9, k + 9, 85);
            world.setBlock(i + 1, j + 9, k + 8, 85);
            world.setBlock(i + 2, j + 9, k + 22, 5);
            world.setBlock(i + 2, j + 9, k + 21, 5);
            world.setBlock(i + 2, j + 9, k + 20, 5);
            world.setBlock(i + 2, j + 9, k + 19, 53);
            world.setBlock(i + 2, j + 9, k + 8, 85);
            world.setBlock(i + 2, j + 9, k + 7, 85);
            world.setBlock(i + 2, j + 9, k + 6, 85);
            world.setBlock(i + 3, j + 9, k + 23, 5);
            world.setBlock(i + 3, j + 9, k + 22, 5);
            world.setBlock(i + 3, j + 9, k + 21, 5);
            world.setBlock(i + 3, j + 9, k + 20, 5);
            world.setBlock(i + 3, j + 9, k + 19, 53);
            world.setBlock(i + 3, j + 9, k + 6, 85);
            world.setBlock(i + 3, j + 9, k + 5, 85);
            world.setBlock(i + 3, j + 9, k + 4, 85);
            world.setBlock(i + 4, j + 9, k + 23, 5);
            world.setBlock(i + 4, j + 9, k + 22, 5);
            world.setBlock(i + 4, j + 9, k + 21, 5);
            world.setBlock(i + 4, j + 9, k + 20, 5);
            world.setBlock(i + 4, j + 9, k + 19, 5);
            world.setBlock(i + 4, j + 9, k + 4, 85);
            world.setBlock(i + 4, j + 9, k + 3, 85);
            world.setBlock(i + 4, j + 9, k + 2, 85);
            world.setBlock(i + 4, j + 9, k + 1, 85);
            world.setBlock(i + 4, j + 9, k + 0, 85);
            world.setBlock(i + 5, j + 9, k + 23, 5);
            world.setBlock(i + 5, j + 9, k + 22, 5);
            world.setBlock(i + 5, j + 9, k + 21, 5);
            world.setBlock(i + 5, j + 9, k + 20, 5);
            world.setBlock(i + 5, j + 9, k + 19, 5);
            world.setBlock(i + 5, j + 9, k + 18, 17);
            world.setBlock(i + 5, j + 9, k + 17, 17);
            world.setBlock(i + 5, j + 9, k + 9, 17);
            world.setBlock(i + 5, j + 9, k + 0, 85);
            world.setBlock(i + 6, j + 9, k + 23, 5);
            world.setBlock(i + 6, j + 9, k + 22, 5);
            world.setBlock(i + 6, j + 9, k + 21, 5);
            world.setBlock(i + 6, j + 9, k + 20, 5);
            world.setBlock(i + 6, j + 9, k + 19, 5);
            world.setBlock(i + 6, j + 9, k + 18, 17);
            world.setBlock(i + 6, j + 9, k + 17, 17);
            world.setBlock(i + 6, j + 9, k + 9, 17);
            world.setBlock(i + 6, j + 9, k + 0, 85);
            world.setBlock(i + 7, j + 9, k + 23, 5);
            world.setBlock(i + 7, j + 9, k + 22, 5);
            world.setBlock(i + 7, j + 9, k + 21, 5);
            world.setBlock(i + 7, j + 9, k + 20, 5);
            world.setBlock(i + 7, j + 9, k + 19, 5);
            world.setBlock(i + 7, j + 9, k + 4, 85);
            world.setBlock(i + 7, j + 9, k + 3, 85);
            world.setBlock(i + 7, j + 9, k + 2, 85);
            world.setBlock(i + 7, j + 9, k + 1, 85);
            world.setBlock(i + 7, j + 9, k + 0, 85);
            world.setBlock(i + 8, j + 9, k + 23, 5);
            world.setBlock(i + 8, j + 9, k + 22, 5);
            world.setBlock(i + 8, j + 9, k + 21, 5);
            world.setBlock(i + 8, j + 9, k + 20, 5);
            world.setBlock(i + 8, j + 9, k + 19, 53);
            world.setBlock(i + 8, j + 9, k + 6, 85);
            world.setBlock(i + 8, j + 9, k + 5, 85);
            world.setBlock(i + 8, j + 9, k + 4, 85);
            world.setBlock(i + 9, j + 9, k + 22, 5);
            world.setBlock(i + 9, j + 9, k + 21, 5);
            world.setBlock(i + 9, j + 9, k + 20, 5);
            world.setBlock(i + 9, j + 9, k + 19, 53);
            world.setBlock(i + 9, j + 9, k + 8, 85);
            world.setBlock(i + 9, j + 9, k + 7, 85);
            world.setBlock(i + 9, j + 9, k + 6, 85);
            world.setBlock(i + 10, j + 9, k + 21, 5);
            world.setBlock(i + 10, j + 9, k + 20, 5);
            world.setBlock(i + 10, j + 9, k + 19, 5);
            world.setBlock(i + 10, j + 9, k + 18, 85);
            world.setBlock(i + 10, j + 9, k + 10, 85);
            world.setBlock(i + 10, j + 9, k + 9, 85);
            world.setBlock(i + 10, j + 9, k + 8, 85);
            world.setBlock(i + 1, j + 10, k + 21, 85);
            world.setBlock(i + 1, j + 10, k + 20, 85);
            world.setBlock(i + 1, j + 10, k + 19, 85);
            world.setBlock(i + 2, j + 10, k + 22, 85);
            world.setBlock(i + 2, j + 10, k + 21, 85);
            world.setBlock(i + 3, j + 10, k + 23, 85);
            world.setBlock(i + 3, j + 10, k + 22, 85);
            world.setBlock(i + 4, j + 10, k + 23, 85);
            world.setBlock(i + 4, j + 10, k + 19, 85);
            world.setBlock(i + 5, j + 10, k + 23, 85);
            world.setBlock(i + 5, j + 10, k + 19, 65);
            world.setBlock(i + 5, j + 10, k + 18, 17);
            world.setBlock(i + 5, j + 10, k + 17, 17);
            world.setBlock(i + 5, j + 10, k + 9, 17);
            world.setBlock(i + 6, j + 10, k + 23, 85);
            world.setBlock(i + 6, j + 10, k + 19, 65);
            world.setBlock(i + 6, j + 10, k + 18, 17);
            world.setBlock(i + 6, j + 10, k + 17, 17);
            world.setBlock(i + 6, j + 10, k + 9, 17);
            world.setBlock(i + 7, j + 10, k + 23, 85);
            world.setBlock(i + 7, j + 10, k + 19, 85);
            world.setBlock(i + 8, j + 10, k + 23, 85);
            world.setBlock(i + 8, j + 10, k + 22, 85);
            world.setBlock(i + 9, j + 10, k + 22, 85);
            world.setBlock(i + 9, j + 10, k + 21, 85);
            world.setBlock(i + 10, j + 10, k + 21, 85);
            world.setBlock(i + 10, j + 10, k + 20, 85);
            world.setBlock(i + 10, j + 10, k + 19, 85);
            world.setBlock(i + 5, j + 11, k + 19, 65);
            world.setBlock(i + 5, j + 11, k + 18, 17);
            world.setBlock(i + 5, j + 11, k + 17, 17);
            world.setBlock(i + 5, j + 11, k + 9, 17);
            world.setBlock(i + 6, j + 11, k + 19, 65);
            world.setBlock(i + 6, j + 11, k + 18, 17);
            world.setBlock(i + 6, j + 11, k + 17, 17);
            world.setBlock(i + 6, j + 11, k + 9, 17);
            world.setBlock(i + 1, j + 12, k + 16, 35);
            world.setBlock(i + 2, j + 12, k + 16, 35);
            world.setBlock(i + 2, j + 12, k + 8, 35);
            world.setBlock(i + 3, j + 12, k + 16, 35);
            world.setBlock(i + 3, j + 12, k + 8, 35);
            world.setBlock(i + 4, j + 12, k + 16, 35);
            world.setBlock(i + 4, j + 12, k + 8, 35);
            world.setBlock(i + 5, j + 12, k + 19, 65);
            world.setBlock(i + 5, j + 12, k + 18, 17);
            world.setBlock(i + 5, j + 12, k + 17, 17);
            world.setBlock(i + 5, j + 12, k + 16, 35);
            world.setBlock(i + 5, j + 12, k + 9, 17);
            world.setBlock(i + 5, j + 12, k + 8, 35);
            world.setBlock(i + 6, j + 12, k + 19, 65);
            world.setBlock(i + 6, j + 12, k + 18, 17);
            world.setBlock(i + 6, j + 12, k + 17, 17);
            world.setBlock(i + 6, j + 12, k + 16, 35);
            world.setBlock(i + 6, j + 12, k + 9, 17);
            world.setBlock(i + 6, j + 12, k + 8, 35);
            world.setBlock(i + 7, j + 12, k + 16, 35);
            world.setBlock(i + 7, j + 12, k + 8, 35);
            world.setBlock(i + 8, j + 12, k + 16, 35);
            world.setBlock(i + 8, j + 12, k + 8, 35);
            world.setBlock(i + 9, j + 12, k + 16, 35);
            world.setBlock(i + 9, j + 12, k + 8, 35);
            world.setBlock(i + 10, j + 12, k + 16, 35);
            world.setBlock(i + 1, j + 13, k + 15, 35);
            world.setBlock(i + 2, j + 13, k + 15, 35);
            world.setBlock(i + 2, j + 13, k + 7, 35);
            world.setBlock(i + 3, j + 13, k + 15, 35);
            world.setBlock(i + 3, j + 13, k + 7, 35);
            world.setBlock(i + 4, j + 13, k + 15, 35);
            world.setBlock(i + 4, j + 13, k + 7, 35);
            world.setBlock(i + 5, j + 13, k + 19, 65);
            world.setBlock(i + 5, j + 13, k + 18, 17);
            world.setBlock(i + 5, j + 13, k + 17, 17);
            world.setBlock(i + 5, j + 13, k + 15, 35);
            world.setBlock(i + 5, j + 13, k + 9, 17);
            world.setBlock(i + 5, j + 13, k + 7, 35);
            world.setBlock(i + 6, j + 13, k + 19, 65);
            world.setBlock(i + 6, j + 13, k + 18, 17);
            world.setBlock(i + 6, j + 13, k + 17, 17);
            world.setBlock(i + 6, j + 13, k + 15, 35);
            world.setBlock(i + 6, j + 13, k + 9, 17);
            world.setBlock(i + 6, j + 13, k + 7, 35);
            world.setBlock(i + 7, j + 13, k + 15, 35);
            world.setBlock(i + 7, j + 13, k + 7, 35);
            world.setBlock(i + 8, j + 13, k + 15, 35);
            world.setBlock(i + 8, j + 13, k + 7, 35);
            world.setBlock(i + 9, j + 13, k + 15, 35);
            world.setBlock(i + 9, j + 13, k + 7, 35);
            world.setBlock(i + 10, j + 13, k + 15, 35);
            world.setBlock(i + 1, j + 14, k + 15, 35);
            world.setBlock(i + 2, j + 14, k + 15, 35);
            world.setBlock(i + 2, j + 14, k + 7, 35);
            world.setBlock(i + 3, j + 14, k + 15, 35);
            world.setBlock(i + 3, j + 14, k + 7, 35);
            world.setBlock(i + 4, j + 14, k + 15, 35);
            world.setBlock(i + 4, j + 14, k + 7, 35);
            world.setBlock(i + 5, j + 14, k + 19, 65);
            world.setBlock(i + 5, j + 14, k + 18, 17);
            world.setBlock(i + 5, j + 14, k + 17, 17);
            world.setBlock(i + 5, j + 14, k + 15, 35);
            world.setBlock(i + 5, j + 14, k + 9, 17);
            world.setBlock(i + 5, j + 14, k + 7, 35);
            world.setBlock(i + 6, j + 14, k + 19, 65);
            world.setBlock(i + 6, j + 14, k + 18, 17);
            world.setBlock(i + 6, j + 14, k + 17, 17);
            world.setBlock(i + 6, j + 14, k + 15, 35);
            world.setBlock(i + 6, j + 14, k + 9, 17);
            world.setBlock(i + 6, j + 14, k + 7, 35);
            world.setBlock(i + 7, j + 14, k + 15, 35);
            world.setBlock(i + 7, j + 14, k + 7, 35);
            world.setBlock(i + 8, j + 14, k + 15, 35);
            world.setBlock(i + 8, j + 14, k + 7, 35);
            world.setBlock(i + 9, j + 14, k + 15, 35);
            world.setBlock(i + 9, j + 14, k + 7, 35);
            world.setBlock(i + 10, j + 14, k + 15, 35);
            world.setBlock(i + 1, j + 15, k + 14, 35);
            world.setBlock(i + 2, j + 15, k + 14, 35);
            world.setBlock(i + 2, j + 15, k + 7, 35);
            world.setBlock(i + 3, j + 15, k + 14, 35);
            world.setBlock(i + 3, j + 15, k + 7, 35);
            world.setBlock(i + 4, j + 15, k + 14, 35);
            world.setBlock(i + 4, j + 15, k + 7, 35);
            world.setBlock(i + 5, j + 15, k + 19, 65);
            world.setBlock(i + 5, j + 15, k + 18, 17);
            world.setBlock(i + 5, j + 15, k + 17, 17);
            world.setBlock(i + 5, j + 15, k + 14, 35);
            world.setBlock(i + 5, j + 15, k + 9, 17);
            world.setBlock(i + 5, j + 15, k + 7, 35);
            world.setBlock(i + 6, j + 15, k + 19, 65);
            world.setBlock(i + 6, j + 15, k + 18, 17);
            world.setBlock(i + 6, j + 15, k + 17, 17);
            world.setBlock(i + 6, j + 15, k + 14, 35);
            world.setBlock(i + 6, j + 15, k + 9, 17);
            world.setBlock(i + 6, j + 15, k + 7, 35);
            world.setBlock(i + 7, j + 15, k + 14, 35);
            world.setBlock(i + 7, j + 15, k + 7, 35);
            world.setBlock(i + 8, j + 15, k + 14, 35);
            world.setBlock(i + 8, j + 15, k + 7, 35);
            world.setBlock(i + 9, j + 15, k + 14, 35);
            world.setBlock(i + 9, j + 15, k + 7, 35);
            world.setBlock(i + 10, j + 15, k + 14, 35);
            world.setBlock(i + 1, j + 16, k + 14, 35);
            world.setBlock(i + 2, j + 16, k + 14, 35);
            world.setBlock(i + 2, j + 16, k + 7, 35);
            world.setBlock(i + 3, j + 16, k + 14, 35);
            world.setBlock(i + 3, j + 16, k + 7, 35);
            world.setBlock(i + 4, j + 16, k + 14, 35);
            world.setBlock(i + 4, j + 16, k + 7, 35);
            world.setBlock(i + 5, j + 16, k + 19, 65);
            world.setBlock(i + 5, j + 16, k + 18, 17);
            world.setBlock(i + 5, j + 16, k + 17, 17);
            world.setBlock(i + 5, j + 16, k + 14, 35);
            world.setBlock(i + 5, j + 16, k + 9, 17);
            world.setBlock(i + 5, j + 16, k + 7, 35);
            world.setBlock(i + 6, j + 16, k + 19, 65);
            world.setBlock(i + 6, j + 16, k + 18, 17);
            world.setBlock(i + 6, j + 16, k + 17, 17);
            world.setBlock(i + 6, j + 16, k + 14, 35);
            world.setBlock(i + 6, j + 16, k + 9, 17);
            world.setBlock(i + 6, j + 16, k + 7, 35);
            world.setBlock(i + 7, j + 16, k + 14, 35);
            world.setBlock(i + 7, j + 16, k + 7, 35);
            world.setBlock(i + 8, j + 16, k + 14, 35);
            world.setBlock(i + 8, j + 16, k + 7, 35);
            world.setBlock(i + 9, j + 16, k + 14, 35);
            world.setBlock(i + 9, j + 16, k + 7, 35);
            world.setBlock(i + 10, j + 16, k + 14, 35);
            world.setBlock(i + 1, j + 17, k + 14, 35);
            world.setBlock(i + 2, j + 17, k + 14, 35);
            world.setBlock(i + 2, j + 17, k + 8, 35);
            world.setBlock(i + 3, j + 17, k + 14, 35);
            world.setBlock(i + 3, j + 17, k + 8, 35);
            world.setBlock(i + 4, j + 17, k + 14, 35);
            world.setBlock(i + 4, j + 17, k + 8, 35);
            world.setBlock(i + 5, j + 17, k + 19, 65);
            world.setBlock(i + 5, j + 17, k + 18, 17);
            world.setBlock(i + 5, j + 17, k + 17, 17);
            world.setBlock(i + 5, j + 17, k + 14, 35);
            world.setBlock(i + 5, j + 17, k + 9, 17);
            world.setBlock(i + 5, j + 17, k + 8, 35);
            world.setBlock(i + 6, j + 17, k + 19, 65);
            world.setBlock(i + 6, j + 17, k + 18, 17);
            world.setBlock(i + 6, j + 17, k + 17, 17);
            world.setBlock(i + 6, j + 17, k + 14, 35);
            world.setBlock(i + 6, j + 17, k + 9, 17);
            world.setBlock(i + 6, j + 17, k + 8, 35);
            world.setBlock(i + 7, j + 17, k + 14, 35);
            world.setBlock(i + 7, j + 17, k + 8, 35);
            world.setBlock(i + 8, j + 17, k + 14, 35);
            world.setBlock(i + 8, j + 17, k + 8, 35);
            world.setBlock(i + 9, j + 17, k + 14, 35);
            world.setBlock(i + 9, j + 17, k + 8, 35);
            world.setBlock(i + 10, j + 17, k + 14, 35);
            world.setBlock(i + 1, j + 18, k + 15, 35);
            world.setBlock(i + 2, j + 18, k + 15, 35);
            world.setBlock(i + 3, j + 18, k + 15, 35);
            world.setBlock(i + 4, j + 18, k + 15, 35);
            world.setBlock(i + 5, j + 18, k + 19, 65);
            world.setBlock(i + 5, j + 18, k + 18, 17);
            world.setBlock(i + 5, j + 18, k + 17, 17);
            world.setBlock(i + 5, j + 18, k + 15, 35);
            world.setBlock(i + 5, j + 18, k + 9, 17);
            world.setBlock(i + 6, j + 18, k + 19, 65);
            world.setBlock(i + 6, j + 18, k + 18, 17);
            world.setBlock(i + 6, j + 18, k + 17, 17);
            world.setBlock(i + 6, j + 18, k + 15, 35);
            world.setBlock(i + 6, j + 18, k + 9, 17);
            world.setBlock(i + 7, j + 18, k + 15, 35);
            world.setBlock(i + 8, j + 18, k + 15, 35);
            world.setBlock(i + 9, j + 18, k + 15, 35);
            world.setBlock(i + 10, j + 18, k + 15, 35);
            world.setBlock(i + 1, j + 19, k + 15, 35);
            world.setBlock(i + 2, j + 19, k + 15, 35);
            world.setBlock(i + 3, j + 19, k + 15, 35);
            world.setBlock(i + 4, j + 19, k + 15, 35);
            world.setBlock(i + 5, j + 19, k + 19, 65);
            world.setBlock(i + 5, j + 19, k + 18, 17);
            world.setBlock(i + 5, j + 19, k + 17, 17);
            world.setBlock(i + 5, j + 19, k + 15, 35);
            world.setBlock(i + 6, j + 19, k + 19, 65);
            world.setBlock(i + 6, j + 19, k + 18, 17);
            world.setBlock(i + 6, j + 19, k + 17, 17);
            world.setBlock(i + 6, j + 19, k + 15, 35);
            world.setBlock(i + 7, j + 19, k + 15, 35);
            world.setBlock(i + 8, j + 19, k + 15, 35);
            world.setBlock(i + 9, j + 19, k + 15, 35);
            world.setBlock(i + 10, j + 19, k + 15, 35);
            world.setBlock(i + 1, j + 20, k + 16, 35);
            world.setBlock(i + 2, j + 20, k + 16, 35);
            world.setBlock(i + 3, j + 20, k + 16, 35);
            world.setBlock(i + 4, j + 20, k + 16, 35);
            world.setBlock(i + 5, j + 20, k + 19, 65);
            world.setBlock(i + 5, j + 20, k + 18, 17);
            world.setBlock(i + 5, j + 20, k + 17, 17);
            world.setBlock(i + 5, j + 20, k + 16, 35);
            world.setBlock(i + 6, j + 20, k + 19, 65);
            world.setBlock(i + 6, j + 20, k + 18, 17);
            world.setBlock(i + 6, j + 20, k + 17, 17);
            world.setBlock(i + 6, j + 20, k + 16, 35);
            world.setBlock(i + 7, j + 20, k + 16, 35);
            world.setBlock(i + 8, j + 20, k + 16, 35);
            world.setBlock(i + 9, j + 20, k + 16, 35);
            world.setBlock(i + 10, j + 20, k + 16, 35);
            world.setBlock(i + 5, j + 21, k + 19, 65);
            world.setBlock(i + 5, j + 21, k + 18, 17);
            world.setBlock(i + 5, j + 21, k + 17, 17);
            world.setBlock(i + 6, j + 21, k + 19, 65);
            world.setBlock(i + 6, j + 21, k + 18, 17);
            world.setBlock(i + 6, j + 21, k + 17, 17);
            world.setBlock(i + 4, j + 22, k + 20, 5);
            world.setBlock(i + 4, j + 22, k + 19, 5);
            world.setBlock(i + 4, j + 22, k + 18, 5);
            world.setBlock(i + 4, j + 22, k + 17, 5);
            world.setBlock(i + 4, j + 22, k + 16, 5);
            world.setBlock(i + 5, j + 22, k + 20, 5);
            world.setBlock(i + 5, j + 22, k + 18, 5);
            world.setBlock(i + 5, j + 22, k + 17, 5);
            world.setBlock(i + 5, j + 22, k + 16, 5);
            world.setBlock(i + 6, j + 22, k + 20, 5);
            world.setBlock(i + 6, j + 22, k + 18, 5);
            world.setBlock(i + 6, j + 22, k + 17, 5);
            world.setBlock(i + 6, j + 22, k + 16, 5);
            world.setBlock(i + 7, j + 22, k + 20, 5);
            world.setBlock(i + 7, j + 22, k + 19, 5);
            world.setBlock(i + 7, j + 22, k + 18, 5);
            world.setBlock(i + 7, j + 22, k + 17, 5);
            world.setBlock(i + 7, j + 22, k + 16, 5);
            world.setBlock(i + 4, j + 23, k + 20, 85);
            world.setBlock(i + 4, j + 23, k + 19, 85);
            world.setBlock(i + 4, j + 23, k + 18, 85);
            world.setBlock(i + 4, j + 23, k + 17, 85);
            world.setBlock(i + 4, j + 23, k + 16, 85);
            world.setBlock(i + 5, j + 23, k + 20, 85);
            world.setBlock(i + 5, j + 23, k + 16, 85);
            world.setBlock(i + 6, j + 23, k + 20, 85);
            world.setBlock(i + 6, j + 23, k + 16, 85);
            world.setBlock(i + 7, j + 23, k + 20, 85);
            world.setBlock(i + 7, j + 23, k + 19, 85);
            world.setBlock(i + 7, j + 23, k + 18, 85);
            world.setBlock(i + 7, j + 23, k + 17, 85);
            world.setBlock(i + 7, j + 23, k + 16, 85);

  return true;
  }
} /*=====End of Code=====*/
